
<!DOCTYPE HTML>

<html lang="en">

<head>
  <meta charset="utf-8">
  <title>numpy.errstate() - NumPy 1.14 - W3cubDocs</title>
  
  <meta name="description" content=" Context manager for floating-point error handling. ">
  <meta name="keywords" content="numpy, errstate, -, numpy~1.14">
  <meta name="HandheldFriendly" content="True">
  <meta name="MobileOptimized" content="320">
  <meta name="viewport" content="width=device-width, initial-scale=1">
  <meta name="mobile-web-app-capable" content="yes">
  
  <link rel="canonical" href="http://docs.w3cub.com/numpy~1.14/generated/numpy.errstate/">
  <link href="/favicon.png" rel="icon">
  <link rel="stylesheet" type="text/css" href="/assets/application-6ca5be81b81eb73e654078d9aaa623884afe18900617ed9a60729a4905026f77.css">
  <script type="text/javascript" src="/assets/application-2fa35d54abf92f248ac868261a14d3f99b325c34fcc70df314719245e248d73c.js"></script>
  <script src="/json/numpy~1.14.js"></script>
  
  <script type="text/javascript">
    var _gaq = _gaq || [];
    _gaq.push(['_setAccount', 'UA-71174418-1']);
    _gaq.push(['_trackPageview']);

    (function() {
      var ga = document.createElement('script'); ga.type = 'text/javascript'; ga.async = true;
      ga.src = ('https:' == document.location.protocol ? 'https://ssl' : 'http://www') + '.google-analytics.com/ga.js';
      var s = document.getElementsByTagName('script')[0]; s.parentNode.insertBefore(ga, s);
    })();
  </script>
  <script async src="//pagead2.googlesyndication.com/pagead/js/adsbygoogle.js"></script>
  <script>
        (adsbygoogle = window.adsbygoogle || []).push({
            google_ad_client: "ca-pub-2572770204602497",
            enable_page_level_ads: true
        });
  </script>
  <script async custom-element="amp-auto-ads"
  src="https://cdn.ampproject.org/v0/amp-auto-ads-0.1.js">
</script>


</head>

<body>
	<div class="_app">
	<header class="_header">
  
  <form class="_search">
    <input type="search" class="_search-input" placeholder="Search&hellip;" autocomplete="off" autocapitalize="off" autocorrect="off" spellcheck="false" maxlength="20">
    <a class="_search-clear"></a>
    <div class="_search-tag"></div>
  </form>
  
  <a class="_home-link" href="/" ></a>
  <a class="_menu-link"></a>
  <h1 class="_logo">
    <a href="/" class="_nav-link" title="API Documentation Browser">W3cubDocs</a>
  </h1>
  
  <span class="_logo-sub-nav">/</span><span class="_logo-sub-nav"><a href="/numpy~1.14/" class="_nav-link" title="" style="margin-left:0;">NumPy 1.14</a></span>
  
  <nav class="_nav">
    <a href="/cheatsheets/" class="_nav-link ">Cheatsheets</a>
    <a href="/about/" class="_nav-link ">About</a>
  </nav>
</header>
	<section class="_sidebar">
		<div class="_list">
			
		</div>
	</section>
	<section class="_container ">
		<div class="_content">
			<div class="_page _sphinx">
				
				
<h1 id="numpy-errstate">numpy.errstate</h1> <dl class="class"> <dt id="numpy.errstate">
<code>class numpy.errstate(**kwargs)</code> <a class="reference external" href="http://github.com/numpy/numpy/blob/v1.14.2/numpy/core/numeric.py#L2790-L2865" target="_blank"><span class="viewcode-link">[source]</span></a>
</dt> <dd>
<p>Context manager for floating-point error handling.</p> <p>Using an instance of <a class="reference internal" href="#numpy.errstate" title="numpy.errstate"><code>errstate</code></a> as a context manager allows statements in that context to execute with a known error handling behavior. Upon entering the context the error handling is set with <a class="reference internal" href="../numpy.seterr/#numpy.seterr" title="numpy.seterr"><code>seterr</code></a> and <a class="reference internal" href="../numpy.seterrcall/#numpy.seterrcall" title="numpy.seterrcall"><code>seterrcall</code></a>, and upon exiting it is reset to what it was before.</p> <table class="docutils field-list" frame="void" rules="none"> <col class="field-name"> <col class="field-body">  <tr>
<th class="field-name">Parameters:</th>
<td class="field-body">
<p class="first"><strong>kwargs</strong> : {divide, over, under, invalid}</p>  <p>Keyword arguments. The valid keywords are the possible floating-point exceptions. Each keyword should have a string value that defines the treatment for the particular error. Possible values are {‘ignore’, ‘warn’, ‘raise’, ‘call’, ‘print’, ‘log’}.</p>  </td> </tr>  </table> <div class="admonition seealso"> <p class="first admonition-title">See also</p> <p class="last"><a class="reference internal" href="../numpy.seterr/#numpy.seterr" title="numpy.seterr"><code>seterr</code></a>, <a class="reference internal" href="../numpy.geterr/#numpy.geterr" title="numpy.geterr"><code>geterr</code></a>, <a class="reference internal" href="../numpy.seterrcall/#numpy.seterrcall" title="numpy.seterrcall"><code>seterrcall</code></a>, <a class="reference internal" href="../numpy.geterrcall/#numpy.geterrcall" title="numpy.geterrcall"><code>geterrcall</code></a></p> </div> <h4 class="rubric">Notes</h4> <p>The <code>with</code> statement was introduced in Python 2.5, and can only be used there by importing it: <code>from __future__ import with_statement</code>. In earlier Python versions the <code>with</code> statement is not available.</p> <p>For complete documentation of the types of floating-point exceptions and treatment options, see <a class="reference internal" href="../numpy.seterr/#numpy.seterr" title="numpy.seterr"><code>seterr</code></a>.</p> <h4 class="rubric">Examples</h4> <pre data-language="python">&gt;&gt;&gt; from __future__ import with_statement  # use 'with' in Python 2.5
&gt;&gt;&gt; olderr = np.seterr(all='ignore')  # Set error handling to known state.
</pre> <pre data-language="python">&gt;&gt;&gt; np.arange(3) / 0.
array([ NaN,  Inf,  Inf])
&gt;&gt;&gt; with np.errstate(divide='warn'):
...     np.arange(3) / 0.
...
__main__:2: RuntimeWarning: divide by zero encountered in divide
array([ NaN,  Inf,  Inf])
</pre> <pre data-language="python">&gt;&gt;&gt; np.sqrt(-1)
nan
&gt;&gt;&gt; with np.errstate(invalid='raise'):
...     np.sqrt(-1)
Traceback (most recent call last):
  File "&lt;stdin&gt;", line 2, in &lt;module&gt;
FloatingPointError: invalid value encountered in sqrt
</pre> <p>Outside the context the error handling behavior has not changed:</p> <pre data-language="python">&gt;&gt;&gt; np.geterr()
{'over': 'warn', 'divide': 'warn', 'invalid': 'warn',
'under': 'ignore'}
</pre> </dd>
</dl>
<div class="_attribution">
  <p class="_attribution-p">
    © 2008–2017 NumPy Developers<br>Licensed under the NumPy License.<br>
    <a href="https://docs.scipy.org/doc/numpy-1.14.2/reference/generated/numpy.errstate.html" class="_attribution-link" target="_blank">https://docs.scipy.org/doc/numpy-1.14.2/reference/generated/numpy.errstate.html</a>
  </p>
</div>

				<amp-auto-ads type="adsense"
              data-ad-client="ca-pub-2572770204602497">
</amp-auto-ads>
			</div>
		</div>
	</section>

	</div>
	<svg style="display:none">
		<symbol id="icon-dir"><svg viewBox="0 0 20 20"><path d="M15 10c0 .3-.305.515-.305.515l-8.56 5.303c-.625.41-1.135.106-1.135-.67V4.853c0-.777.51-1.078 1.135-.67l8.56 5.305S15 9.702 15 10z"/></svg></symbol>
	  </svg>
</body>
</html>
